<?xml version="1.0" ?>
<!-- Generated using onshape-to-robot -->
<!-- Onshape document_id: f494e174d964f52a4d6ec25c -->
<mujoco model="robot_env">
  <compiler angle="radian" meshdir="assets" autolimits="true"/>
  <default>
    <default class="robot_env">
      <joint frictionloss="0.1" armature="0.005"/>
      <position kp="50" dampratio="1"/>
      <default class="visual">
        <geom type="mesh" contype="0" conaffinity="0" group="2"/>
      </default>
      <default class="collision">
        <geom group="3"/>
      </default>
    </default>
  </default>
  <worldbody>
    <!-- Link body -->
    <body name="body" pos="0 0 .552" quat="1 0 0 0" childclass="robot_env">
      <freejoint name="body_freejoint"/>
      <inertial pos="5.07515e-11 0.024907 -0.0163937" mass="7.19122" fullinertia="0.0520022 0.0720446 0.0228789 3.38177e-10 4.47057e-11 -9.40186e-05"/>
      <!-- Part dc07_00a_dummy_none -->
      <geom type="mesh" class="visual" pos="0.065 0.0125 -0.15275" quat="1.04668e-15 1 1.13187e-25 3.23148e-17" mesh="dc07_00a_dummy_none" material="dc07_00a_dummy_none_material"/>
      <geom type="mesh" class="collision" pos="0.065 0.0125 -0.15275" quat="1.04668e-15 1 1.13187e-25 3.23148e-17" mesh="dc07_00a_dummy_none" material="dc07_00a_dummy_none_material"/>
      <!-- Part shoulder_extension_motor -->
      <geom type="mesh" class="visual" pos="0.071 0.025 0.065976" quat="1 1.23661e-16 -5.55112e-17 1.38778e-16" mesh="shoulder_extension_motor" material="shoulder_extension_motor_material"/>
      <geom type="mesh" class="collision" pos="0.071 0.025 0.065976" quat="1 1.23661e-16 -5.55112e-17 1.38778e-16" mesh="shoulder_extension_motor" material="shoulder_extension_motor_material"/>
      <!-- Part shoulder_extension_motor_2 -->
      <geom type="mesh" class="visual" pos="-0.071 0.025 0.065976" quat="1.55822e-15 6.11073e-17 -3.36536e-16 1" mesh="shoulder_extension_motor" material="shoulder_extension_motor_material"/>
      <geom type="mesh" class="collision" pos="-0.071 0.025 0.065976" quat="1.55822e-15 6.11073e-17 -3.36536e-16 1" mesh="shoulder_extension_motor" material="shoulder_extension_motor_material"/>
      <!-- Part part_1 -->
      <geom type="mesh" class="visual" pos="6.2797e-16 0.025 -0.135" quat="1 0 0 2.95823e-31" mesh="part_1" material="part_1_material"/>
      <geom type="mesh" class="collision" pos="6.2797e-16 0.025 -0.135" quat="1 0 0 2.95823e-31" mesh="part_1" material="part_1_material"/>
      <!-- Part body -->
      <geom type="mesh" class="visual" pos="-0.09 0.05 -0.12" quat="1 0 0 0" mesh="body" material="body_material"/>
      <geom type="mesh" class="collision" pos="-0.09 0.05 -0.12" quat="1 0 0 0" mesh="body" material="body_material"/>
      <!-- Part dc07_00a_dummy_none_2 -->
      <geom type="mesh" class="visual" pos="-0.065 0.0125 -0.15275" quat="1.04668e-15 1 1.15384e-25 3.92537e-17" mesh="dc07_00a_dummy_none" material="dc07_00a_dummy_none_material"/>
      <geom type="mesh" class="collision" pos="-0.065 0.0125 -0.15275" quat="1.04668e-15 1 1.15384e-25 3.92537e-17" mesh="dc07_00a_dummy_none" material="dc07_00a_dummy_none_material"/>
      <!-- Part part_2 -->
      <geom type="mesh" class="visual" pos="4.16334e-17 0.025 0.12" quat="1 -7.82437e-17 -0 5.30825e-16" mesh="part_2" material="part_2_material"/>
      <geom type="mesh" class="collision" pos="4.16334e-17 0.025 0.12" quat="1 -7.82437e-17 -0 5.30825e-16" mesh="part_2" material="part_2_material"/>
      <!-- Part part_1_2 -->
      <geom type="mesh" class="visual" pos="4.16334e-17 0.025 0.12" quat="1 -1.81927e-16 0 5.34295e-16" mesh="part_1__2" material="part_1__2_material"/>
      <geom type="mesh" class="collision" pos="4.16334e-17 0.025 0.12" quat="1 -1.81927e-16 0 5.34295e-16" mesh="part_1__2" material="part_1__2_material"/>
      <!-- Link shoulder_link -->
      <body name="shoulder_link" pos="0.092 0.025 0.104476" quat="0.707107 4.25547e-16 -0.707107 3.33067e-16">
        <!-- Joint from body to shoulder_link -->
        <joint axis="0 0 1" name=" Shoulder front and back right" type="hinge" range="-1.5707963267948966 1.5707963267948966"/>
        <inertial pos="-0.00571829 -1.033e-08 -0.00978897" mass="0.0312537" fullinertia="1.30191e-05 5.64649e-06 1.38435e-05 -5.24922e-12 -1.80302e-06 -5.43041e-12"/>
        <!-- Part shoulder_link -->
        <geom type="mesh" class="visual" pos="-0.011 -0.024127 1.38778e-17" quat="0.5 0.5 0.5 -0.5" mesh="shoulder_link" material="shoulder_link_material"/>
        <geom type="mesh" class="collision" pos="-0.011 -0.024127 1.38778e-17" quat="0.5 0.5 0.5 -0.5" mesh="shoulder_link" material="shoulder_link_material"/>
        <!-- Link shoulder_extension_motor -->
        <body name="shoulder_extension_motor" pos="-0.019 0.020127 -0.022" quat="0.5 -0.5 0.5 0.5">
          <!-- Joint from shoulder_link to shoulder_extension_motor -->
          <joint axis="0 0 1" name="Shoulder right lateral" type="hinge" range="-3.1415926535897922 8.881784197001252e-16"/>
          <inertial pos="-4.37745e-09 0.0335095 -0.0190665" mass="0.47136" fullinertia="0.000788471 7.59222e-05 0.000760928 -1.12984e-10 -1.83295e-11 -1.00061e-05"/>
          <!-- Part arm_to_hand_link -->
          <geom type="mesh" class="visual" pos="-1.38778e-17 0.145 -0.04185" quat="0.707107 0.707107 4.44089e-16 -9.58802e-16" mesh="arm_to_hand_link" material="arm_to_hand_link_material"/>
          <geom type="mesh" class="collision" pos="-1.38778e-17 0.145 -0.04185" quat="0.707107 0.707107 4.44089e-16 -9.58802e-16" mesh="arm_to_hand_link" material="arm_to_hand_link_material"/>
          <!-- Part shoulder_to_arm_link -->
          <geom type="mesh" class="visual" pos="2.77556e-17 0.0325 0.0018" quat="0.5 0.5 0.5 -0.5" mesh="shoulder_to_arm_link" material="shoulder_to_arm_link_material"/>
          <geom type="mesh" class="collision" pos="2.77556e-17 0.0325 0.0018" quat="0.5 0.5 0.5 -0.5" mesh="shoulder_to_arm_link" material="shoulder_to_arm_link_material"/>
          <!-- Part shoulder_extension_motor_3 -->
          <geom type="mesh" class="visual" pos="0 0.0385 -0.0182" quat="0.5 0.5 0.5 -0.5" mesh="shoulder_extension_motor" material="shoulder_extension_motor_material"/>
          <geom type="mesh" class="collision" pos="0 0.0385 -0.0182" quat="0.5 0.5 0.5 -0.5" mesh="shoulder_extension_motor" material="shoulder_extension_motor_material"/>
          <!-- Part peg -->
          <geom type="mesh" class="visual" pos="1.38778e-17 0.12 -0.0182" quat="0.707107 0.707107 6.66134e-16 -6.75059e-16" mesh="peg" material="peg_material"/>
          <geom type="mesh" class="collision" pos="1.38778e-17 0.12 -0.0182" quat="0.707107 0.707107 6.66134e-16 -6.75059e-16" mesh="peg" material="peg_material"/>
          <!-- Link shoulder_extension_motor_2 -->
          <body name="shoulder_extension_motor_2" pos="8.32667e-17 0.145 0.00145" quat="1 -0 5.55112e-16 -2.22045e-16">
            <!-- Joint from shoulder_extension_motor to shoulder_extension_motor_2 -->
            <joint axis="0 0 1" name="right wrist" type="hinge" range="-1.5707963267948957 0.5235987755982997"/>
            <inertial pos="-6.11201e-09 0.012611 -0.0194098" mass="0.33759" fullinertia="9.80176e-05 5.43169e-05 8.19654e-05 -6.98624e-11 -1.84776e-11 -1.47092e-06"/>
            <!-- Part shoulder_extension_motor_4 -->
            <geom type="mesh" class="visual" pos="-1.38778e-17 0.0385 -0.0182" quat="0.5 0.5 0.5 -0.5" mesh="shoulder_extension_motor" material="shoulder_extension_motor_material"/>
            <geom type="mesh" class="collision" pos="-1.38778e-17 0.0385 -0.0182" quat="0.5 0.5 0.5 -0.5" mesh="shoulder_extension_motor" material="shoulder_extension_motor_material"/>
            <!-- Part arm_link -->
            <geom type="mesh" class="visual" pos="-5.05103e-05 0.0325 -0.0382" quat="0.5 0.5 -0.5 0.5" mesh="arm_link" material="arm_link_material"/>
            <geom type="mesh" class="collision" pos="-5.05103e-05 0.0325 -0.0382" quat="0.5 0.5 -0.5 0.5" mesh="arm_link" material="arm_link_material"/>
          </body>
        </body>
      </body>
      <!-- Link shoulder_link_2 -->
      <body name="shoulder_link_2" pos="-0.092 0.025 0.104476" quat="7.00132e-16 -0.707107 -1.11022e-16 -0.707107">
        <!-- Joint from body to shoulder_link_2 -->
        <joint axis="0 0 1" name="Shoulder left front back" type="hinge" range="-1.570796326794893 1.5707963267949"/>
        <inertial pos="-0.00571829 -1.033e-08 -0.00978897" mass="0.0312537" fullinertia="1.30191e-05 5.64649e-06 1.38435e-05 -5.24922e-12 -1.80302e-06 -5.43041e-12"/>
        <!-- Part shoulder_link_2 -->
        <geom type="mesh" class="visual" pos="-0.011 -0.024127 0" quat="0.5 0.5 0.5 -0.5" mesh="shoulder_link" material="shoulder_link_material"/>
        <geom type="mesh" class="collision" pos="-0.011 -0.024127 0" quat="0.5 0.5 0.5 -0.5" mesh="shoulder_link" material="shoulder_link_material"/>
        <!-- Link shoulder_extension_motor_3 -->
        <body name="shoulder_extension_motor_3" pos="-0.019 0.020127 -0.022" quat="0.5 -0.5 0.5 0.5">
          <!-- Joint from shoulder_link_2 to shoulder_extension_motor_3 -->
          <joint axis="0 0 1" name="shoulder left lateral" type="hinge" range="-3.1415926535897922 8.881784197001252e-16"/>
          <inertial pos="-4.37745e-09 0.0335095 -0.0190665" mass="0.47136" fullinertia="0.000788471 7.59222e-05 0.000760928 -1.12984e-10 -1.83295e-11 -1.00061e-05"/>
          <!-- Part arm_to_hand_link_2 -->
          <geom type="mesh" class="visual" pos="1.66533e-16 0.145 -0.04185" quat="0.707107 0.707107 0 8.46076e-17" mesh="arm_to_hand_link" material="arm_to_hand_link_material"/>
          <geom type="mesh" class="collision" pos="1.66533e-16 0.145 -0.04185" quat="0.707107 0.707107 0 8.46076e-17" mesh="arm_to_hand_link" material="arm_to_hand_link_material"/>
          <!-- Part peg_2 -->
          <geom type="mesh" class="visual" pos="1.38778e-16 0.12 -0.0182" quat="0.707107 0.707107 2.22045e-16 1.83844e-16" mesh="peg" material="peg_material"/>
          <geom type="mesh" class="collision" pos="1.38778e-16 0.12 -0.0182" quat="0.707107 0.707107 2.22045e-16 1.83844e-16" mesh="peg" material="peg_material"/>
          <!-- Part shoulder_to_arm_link_2 -->
          <geom type="mesh" class="visual" pos="-2.77556e-17 0.0325 0.0018" quat="0.5 0.5 0.5 -0.5" mesh="shoulder_to_arm_link" material="shoulder_to_arm_link_material"/>
          <geom type="mesh" class="collision" pos="-2.77556e-17 0.0325 0.0018" quat="0.5 0.5 0.5 -0.5" mesh="shoulder_to_arm_link" material="shoulder_to_arm_link_material"/>
          <!-- Part shoulder_extension_motor_5 -->
          <geom type="mesh" class="visual" pos="-1.38778e-17 0.0385 -0.0182" quat="0.5 0.5 0.5 -0.5" mesh="shoulder_extension_motor" material="shoulder_extension_motor_material"/>
          <geom type="mesh" class="collision" pos="-1.38778e-17 0.0385 -0.0182" quat="0.5 0.5 0.5 -0.5" mesh="shoulder_extension_motor" material="shoulder_extension_motor_material"/>
          <!-- Link shoulder_extension_motor_4 -->
          <body name="shoulder_extension_motor_4" pos="9.71445e-17 0.145 0.00145" quat="1 3.01695e-16 -8.32667e-17 1.12757e-16">
            <!-- Joint from shoulder_extension_motor_3 to shoulder_extension_motor_4 -->
            <joint axis="0 0 1" name="left hand" type="hinge" range="-1.5707963267948966 0.5235987755982988"/>
            <inertial pos="-6.11201e-09 0.012611 -0.0194098" mass="0.33759" fullinertia="9.80176e-05 5.43169e-05 8.19654e-05 -6.98624e-11 -1.84776e-11 -1.47092e-06"/>
            <!-- Part arm_link_2 -->
            <geom type="mesh" class="visual" pos="-5.05103e-05 0.0325 -0.0382" quat="0.5 0.5 -0.5 0.5" mesh="arm_link" material="arm_link_material"/>
            <geom type="mesh" class="collision" pos="-5.05103e-05 0.0325 -0.0382" quat="0.5 0.5 -0.5 0.5" mesh="arm_link" material="arm_link_material"/>
            <!-- Part shoulder_extension_motor_6 -->
            <geom type="mesh" class="visual" pos="0 0.0385 -0.0182" quat="0.5 0.5 0.5 -0.5" mesh="shoulder_extension_motor" material="shoulder_extension_motor_material"/>
            <geom type="mesh" class="collision" pos="0 0.0385 -0.0182" quat="0.5 0.5 0.5 -0.5" mesh="shoulder_extension_motor" material="shoulder_extension_motor_material"/>
          </body>
        </body>
      </body>
      <!-- Link part_1 -->
      <body name="part_1" pos="0.065 0.0125 -0.1745" quat="3.25616e-17 -3.221e-17 1.11022e-15 1">
        <!-- Joint from body to part_1 -->
        <joint axis="0 0 1" name="right leg twist" type="hinge" range="-0.5235987755982988 0.5235987755982988"/>
        <inertial pos="0 0 0" mass="1e-09" fullinertia="1e-09 1e-09 1e-09 0 0 0"/>
        <!-- Part part_1_3 -->
        <geom type="mesh" class="visual" pos="-8.85663e-05 -0.0255 -0.03195" quat="0 1 0 0" mesh="part_1__3" material="part_1__3_material"/>
        <geom type="mesh" class="collision" pos="-8.85663e-05 -0.0255 -0.03195" quat="0 1 0 0" mesh="part_1__3" material="part_1__3_material"/>
        <!-- Link part_1_2 -->
        <body name="part_1_2" pos="-8.85663e-05 0.0205 -0.03195" quat="0.707107 -0.707107 0 6.1669e-33">
          <!-- Joint from part_1 to part_1_2 -->
          <joint axis="0 0 1" name="right leg lateral" type="hinge" range="-1.047197551196594 1.0471975511966012"/>
          <inertial pos="-3.38415e-05 0.0123477 -0.0441492" mass="0.707082" fullinertia="0.000559482 0.000502965 0.000187975 1.42758e-06 -2.65164e-07 -9.43743e-06"/>
          <!-- Part part_1_4 -->
          <geom type="mesh" class="visual" pos="-5.39421e-10 -0.0085 -0.00675" quat="0.707107 -0.707107 -2.17342e-09 -2.17342e-09" mesh="part_1__4" material="part_1__4_material"/>
          <geom type="mesh" class="collision" pos="-5.39421e-10 -0.0085 -0.00675" quat="0.707107 -0.707107 -2.17342e-09 -2.17342e-09" mesh="part_1__4" material="part_1__4_material"/>
          <!-- Part dc07_00a_dummy_none_3 -->
          <geom type="mesh" class="visual" pos="-5.00004e-05 0.025 -0.022" quat="0.707107 -2.59329e-17 -0.707107 2.22045e-16" mesh="dc07_00a_dummy_none" material="dc07_00a_dummy_none_material"/>
          <geom type="mesh" class="collision" pos="-5.00004e-05 0.025 -0.022" quat="0.707107 -2.59329e-17 -0.707107 2.22045e-16" mesh="dc07_00a_dummy_none" material="dc07_00a_dummy_none_material"/>
          <!-- Part part_1_5 -->
          <geom type="mesh" class="visual" pos="-0.01505 0.0125 -0.037" quat="0.5 0.5 0.5 -0.5" mesh="part_1__5" material="part_1__5_material"/>
          <geom type="mesh" class="collision" pos="-0.01505 0.0125 -0.037" quat="0.5 0.5 0.5 -0.5" mesh="part_1__5" material="part_1__5_material"/>
          <!-- Part part_1_6 -->
          <geom type="mesh" class="visual" pos="0.01495 0.0125 -0.037" quat="0.5 -0.5 0.5 0.5" mesh="part_1__5" material="part_1__5_material"/>
          <geom type="mesh" class="collision" pos="0.01495 0.0125 -0.037" quat="0.5 -0.5 0.5 0.5" mesh="part_1__5" material="part_1__5_material"/>
          <!-- Part dc07_00a_dummy_none_4 -->
          <geom type="mesh" class="visual" pos="-5.00001e-05 4.71845e-16 -0.06775" quat="1.23915e-16 3.50267e-09 3.33067e-16 -1" mesh="dc07_00a_dummy_none" material="dc07_00a_dummy_none_material"/>
          <geom type="mesh" class="collision" pos="-5.00001e-05 4.71845e-16 -0.06775" quat="1.23915e-16 3.50267e-09 3.33067e-16 -1" mesh="dc07_00a_dummy_none" material="dc07_00a_dummy_none_material"/>
          <!-- Link dc07_00a_dummy_none -->
          <body name="dc07_00a_dummy_none" pos="-0.0178 0.025 -0.022" quat="2.46005e-17 0.707107 1.11022e-16 0.707107">
            <!-- Joint from part_1_2 to dc07_00a_dummy_none -->
            <joint axis="0 0 1" name="right hammy" type="hinge" range="-3.907985046680551e-14 1.5707963267948575"/>
            <inertial pos="8.87415e-05 -0.0909428 0.017692" mass="0.597955" fullinertia="0.000946989 0.000241356 0.00076487 -9.4812e-09 -4.40927e-12 1.1703e-06"/>
            <!-- Part part_1_7 -->
            <geom type="mesh" class="visual" pos="8.85663e-05 -6.66134e-16 0.04442" quat="1.00475e-14 1.43579e-14 0.707107 0.707107" mesh="part_1__6" material="part_1__6_material"/>
            <geom type="mesh" class="collision" pos="8.85663e-05 -6.66134e-16 0.04442" quat="1.00475e-14 1.43579e-14 0.707107 0.707107" mesh="part_1__6" material="part_1__6_material"/>
            <!-- Part peg_3 -->
            <geom type="mesh" class="visual" pos="8.85663e-05 -0.10395 -0.009665" quat="1.0103e-14 1.51239e-14 0.707107 0.707107" mesh="peg" material="peg_material"/>
            <geom type="mesh" class="collision" pos="8.85663e-05 -0.10395 -0.009665" quat="1.0103e-14 1.51239e-14 0.707107 0.707107" mesh="peg" material="peg_material"/>
            <!-- Part peg_4 -->
            <geom type="mesh" class="visual" pos="8.85663e-05 -0.10395 0.045085" quat="9.60343e-15 1.4689e-14 0.707107 0.707107" mesh="peg" material="peg_material"/>
            <geom type="mesh" class="collision" pos="8.85663e-05 -0.10395 0.045085" quat="9.60343e-15 1.4689e-14 0.707107 0.707107" mesh="peg" material="peg_material"/>
            <!-- Part part_1_8 -->
            <geom type="mesh" class="visual" pos="8.85663e-05 -0.08895 0.045085" quat="0.5 -0.5 -0.5 -0.5" mesh="part_1__7" material="part_1__7_material"/>
            <geom type="mesh" class="collision" pos="8.85663e-05 -0.08895 0.045085" quat="0.5 -0.5 -0.5 -0.5" mesh="part_1__7" material="part_1__7_material"/>
            <!-- Part dc07_00a_dummy_none_5 -->
            <geom type="mesh" class="visual" pos="8.85663e-05 -0.12695 0.01771" quat="1.78468e-14 3.68255e-15 5.55112e-16 1" mesh="dc07_00a_dummy_none" material="dc07_00a_dummy_none_material"/>
            <geom type="mesh" class="collision" pos="8.85663e-05 -0.12695 0.01771" quat="1.78468e-14 3.68255e-15 5.55112e-16 1" mesh="dc07_00a_dummy_none" material="dc07_00a_dummy_none_material"/>
            <!-- Part part_1_9 -->
            <geom type="mesh" class="visual" pos="8.85663e-05 -0.08895 -0.009665" quat="0.5 -0.5 0.5 0.5" mesh="part_1__7" material="part_1__7_material"/>
            <geom type="mesh" class="collision" pos="8.85663e-05 -0.08895 -0.009665" quat="0.5 -0.5 0.5 0.5" mesh="part_1__7" material="part_1__7_material"/>
            <!-- Link part_1_3 -->
            <body name="part_1_3" pos="8.85663e-05 -0.12695 0.03546" quat="3.67935e-15 -1.78413e-14 -1 5.82867e-16">
              <!-- Joint from dc07_00a_dummy_none to part_1_3 -->
              <joint axis="0 0 1" name="right knee" type="hinge" range="-1.570796326794932 1.570796326794861"/>
              <inertial pos="-8.85412e-05 -0.0702967 0.01771" mass="0.195615" fullinertia="0.000327822 5.05789e-05 0.000288749 1.56531e-08 2.25082e-19 2.46587e-19"/>
              <!-- Part peg_5 -->
              <geom type="mesh" class="visual" pos="-8.85663e-05 -0.10395 0.01771" quat="0.707107 -0.707107 1.22125e-14 -1.29728e-14" mesh="peg" material="peg_material"/>
              <geom type="mesh" class="collision" pos="-8.85663e-05 -0.10395 0.01771" quat="0.707107 -0.707107 1.22125e-14 -1.29728e-14" mesh="peg" material="peg_material"/>
              <!-- Part part_1_10 -->
              <geom type="mesh" class="visual" pos="-8.85663e-05 0 -0.009" quat="0.707107 -0.707107 1.22125e-14 -1.3017e-14" mesh="part_1__8" material="part_1__8_material"/>
              <geom type="mesh" class="collision" pos="-8.85663e-05 0 -0.009" quat="0.707107 -0.707107 1.22125e-14 -1.3017e-14" mesh="part_1__8" material="part_1__8_material"/>
              <!-- Part part_1_11 -->
              <geom type="mesh" class="visual" pos="-8.85663e-05 -0.15385 -0.009" quat="1.20112e-14 -1.31232e-14 -0.707107 0.707107" mesh="part_1__9" material="part_1__9_material"/>
              <geom type="mesh" class="collision" pos="-8.85663e-05 -0.15385 -0.009" quat="1.20112e-14 -1.31232e-14 -0.707107 0.707107" mesh="part_1__9" material="part_1__9_material"/>
              <!-- Link part_1_4 -->
              <body name="part_1_4" pos="-0.000177133 -0.15385 0.03942" quat="1.77636e-14 -7.84833e-16 5.55112e-16 1">
                <!-- Joint from part_1_3 to part_1_4 -->
                <joint axis="0 0 1" name="right foot" type="hinge" range="-1.570796326794853 0.5235987755983423"/>
                <inertial pos="-0.0221492 -0.0114021 -0.0217662" mass="0.707082" fullinertia="0.000187139 0.000502965 0.000558646 -5.372e-06 2.65156e-07 -1.4311e-06"/>
                <!-- Part part_1_12 -->
                <geom type="mesh" class="visual" pos="-0.015 -0.0125 -0.03675" quat="1.52473e-14 1.51403e-14 0.707107 0.707107" mesh="part_1__5" material="part_1__5_material"/>
                <geom type="mesh" class="collision" pos="-0.015 -0.0125 -0.03675" quat="1.52473e-14 1.51403e-14 0.707107 0.707107" mesh="part_1__5" material="part_1__5_material"/>
                <!-- Part dc07_00a_dummy_none_6 -->
                <geom type="mesh" class="visual" pos="-0.04575 1.77636e-15 -0.02175" quat="0.707107 -1.02913e-14 0.707107 -4.0485e-14" mesh="dc07_00a_dummy_none" material="dc07_00a_dummy_none_material"/>
                <geom type="mesh" class="collision" pos="-0.04575 1.77636e-15 -0.02175" quat="0.707107 -1.02913e-14 0.707107 -4.0485e-14" mesh="dc07_00a_dummy_none" material="dc07_00a_dummy_none_material"/>
                <!-- Part dc07_00a_dummy_none_7 -->
                <geom type="mesh" class="visual" pos="6.11663e-15 -3.33067e-16 -0.02175" quat="1 -3.57897e-14 3.33067e-16 -2.16119e-14" mesh="dc07_00a_dummy_none" material="dc07_00a_dummy_none_material"/>
                <geom type="mesh" class="collision" pos="6.11663e-15 -3.33067e-16 -0.02175" quat="1 -3.57897e-14 3.33067e-16 -2.16119e-14" mesh="dc07_00a_dummy_none" material="dc07_00a_dummy_none_material"/>
                <!-- Part part_1_13 -->
                <geom type="mesh" class="visual" pos="0.01525 0.0085 -0.0218" quat="0.5 0.5 -0.5 0.5" mesh="part_1__4" material="part_1__4_material"/>
                <geom type="mesh" class="collision" pos="0.01525 0.0085 -0.0218" quat="0.5 0.5 -0.5 0.5" mesh="part_1__4" material="part_1__4_material"/>
                <!-- Part part_1_14 -->
                <geom type="mesh" class="visual" pos="-0.015 -0.0125 -0.00675" quat="1.5299e-14 -1.53038e-14 -0.707107 0.707107" mesh="part_1__5" material="part_1__5_material"/>
                <geom type="mesh" class="collision" pos="-0.015 -0.0125 -0.00675" quat="1.5299e-14 -1.53038e-14 -0.707107 0.707107" mesh="part_1__5" material="part_1__5_material"/>
                <!-- Link part_1_5 -->
                <body name="part_1_5" pos="0.022 1.86517e-14 -0.0218" quat="0.707107 -1.19644e-14 -0.707107 -1.1352e-14">
                  <!-- Joint from part_1_4 to part_1_5 -->
                  <joint axis="0 0 1" name="right foot twist" type="hinge" range="-0.523598775598226 0.5235987755983716"/>
                  <inertial pos="-1.32219e-06 0.0214439 0.0199037" mass="0.0378211" fullinertia="1.63936e-05 1.44949e-05 5.01369e-06 -1.03364e-09 1.17998e-09 -4.80658e-07"/>
                  <!-- Part part_1_15 -->
                  <geom type="mesh" class="visual" pos="0.007 0.03695 0.0205" quat="0.707107 0.707107 2.77556e-15 -3.20888e-15" mesh="part_1__10" material="part_1__10_material"/>
                  <geom type="mesh" class="collision" pos="0.007 0.03695 0.0205" quat="0.707107 0.707107 2.77556e-15 -3.20888e-15" mesh="part_1__10" material="part_1__10_material"/>
                  <!-- Part part_1_16 -->
                  <geom type="mesh" class="visual" pos="0 0 0.046" quat="0.707107 0.707107 -0 -2.51823e-25" mesh="part_1__11" material="part_1__11_material"/>
                  <geom type="mesh" class="collision" pos="0 0 0.046" quat="0.707107 0.707107 -0 -2.51823e-25" mesh="part_1__11" material="part_1__11_material"/>
                </body>
              </body>
            </body>
          </body>
        </body>
      </body>
      <!-- Link part_1_6 -->
      <body name="part_1_6" pos="-0.065 0.0125 -0.1745" quat="8.07806e-17 8.62114e-16 -6.66134e-16 -1">
        <!-- Joint from body to part_1_6 -->
        <joint axis="0 0 1" name="left leg twist" type="hinge" range="-0.523598775598297 0.5235987755983006"/>
        <inertial pos="0 0 0" mass="1e-09" fullinertia="1e-09 1e-09 1e-09 0 0 0"/>
        <!-- Part part_1_17 -->
        <geom type="mesh" class="visual" pos="-8.85663e-05 -0.0255 -0.03195" quat="0 1 0 0" mesh="part_1__3" material="part_1__3_material"/>
        <geom type="mesh" class="collision" pos="-8.85663e-05 -0.0255 -0.03195" quat="0 1 0 0" mesh="part_1__3" material="part_1__3_material"/>
        <!-- Link part_1_7 -->
        <body name="part_1_7" pos="-8.85663e-05 0.0205 -0.03195" quat="0.707107 -0.707107 0 -4.79509e-34">
          <!-- Joint from part_1_6 to part_1_7 -->
          <joint axis="0 0 1" name="left leg lateral" type="hinge" range="-1.0471975511965959 1.0471975511965994"/>
          <inertial pos="-3.38415e-05 0.0123477 -0.0441492" mass="0.707082" fullinertia="0.000559482 0.000502965 0.000187975 1.42758e-06 -2.65164e-07 -9.43743e-06"/>
          <!-- Part part_1_18 -->
          <geom type="mesh" class="visual" pos="0.01495 0.0125 -0.037" quat="0.5 -0.5 0.5 0.5" mesh="part_1__5" material="part_1__5_material"/>
          <geom type="mesh" class="collision" pos="0.01495 0.0125 -0.037" quat="0.5 -0.5 0.5 0.5" mesh="part_1__5" material="part_1__5_material"/>
          <!-- Part dc07_00a_dummy_none_8 -->
          <geom type="mesh" class="visual" pos="-5.00001e-05 -5.55112e-17 -0.06775" quat="9.05687e-16 3.50267e-09 0 -1" mesh="dc07_00a_dummy_none" material="dc07_00a_dummy_none_material"/>
          <geom type="mesh" class="collision" pos="-5.00001e-05 -5.55112e-17 -0.06775" quat="9.05687e-16 3.50267e-09 0 -1" mesh="dc07_00a_dummy_none" material="dc07_00a_dummy_none_material"/>
          <!-- Part dc07_00a_dummy_none_9 -->
          <geom type="mesh" class="visual" pos="-5.00004e-05 0.025 -0.022" quat="0.707107 7.38434e-16 -0.707107 5.56892e-16" mesh="dc07_00a_dummy_none" material="dc07_00a_dummy_none_material"/>
          <geom type="mesh" class="collision" pos="-5.00004e-05 0.025 -0.022" quat="0.707107 7.38434e-16 -0.707107 5.56892e-16" mesh="dc07_00a_dummy_none" material="dc07_00a_dummy_none_material"/>
          <!-- Part part_1_19 -->
          <geom type="mesh" class="visual" pos="-0.01505 0.0125 -0.037" quat="0.5 0.5 0.5 -0.5" mesh="part_1__5" material="part_1__5_material"/>
          <geom type="mesh" class="collision" pos="-0.01505 0.0125 -0.037" quat="0.5 0.5 0.5 -0.5" mesh="part_1__5" material="part_1__5_material"/>
          <!-- Part part_1_20 -->
          <geom type="mesh" class="visual" pos="-5.39421e-10 -0.0085 -0.00675" quat="0.707107 -0.707107 -2.17342e-09 -2.17342e-09" mesh="part_1__4" material="part_1__4_material"/>
          <geom type="mesh" class="collision" pos="-5.39421e-10 -0.0085 -0.00675" quat="0.707107 -0.707107 -2.17342e-09 -2.17342e-09" mesh="part_1__4" material="part_1__4_material"/>
          <!-- Link dc07_00a_dummy_none_2 -->
          <body name="dc07_00a_dummy_none_2" pos="-0.0178 0.025 -0.022" quat="7.38434e-16 -0.707107 -6.66134e-16 -0.707107">
            <!-- Joint from part_1_7 to dc07_00a_dummy_none_2 -->
            <joint axis="0 0 1" name="left hammy" type="hinge" range="-8.881784197001252e-16 1.5707963267948957"/>
            <inertial pos="8.87415e-05 -0.0909428 0.017692" mass="0.597955" fullinertia="0.000946989 0.000241356 0.00076487 -9.4812e-09 -4.40926e-12 1.1703e-06"/>
            <!-- Part part_1_21 -->
            <geom type="mesh" class="visual" pos="8.85663e-05 2.77556e-17 0.04442" quat="3.33067e-16 -4.70426e-17 -0.707107 -0.707107" mesh="part_1__6" material="part_1__6_material"/>
            <geom type="mesh" class="collision" pos="8.85663e-05 2.77556e-17 0.04442" quat="3.33067e-16 -4.70426e-17 -0.707107 -0.707107" mesh="part_1__6" material="part_1__6_material"/>
            <!-- Part part_1_22 -->
            <geom type="mesh" class="visual" pos="8.85663e-05 -0.08895 0.045085" quat="0.5 -0.5 -0.5 -0.5" mesh="part_1__7" material="part_1__7_material"/>
            <geom type="mesh" class="collision" pos="8.85663e-05 -0.08895 0.045085" quat="0.5 -0.5 -0.5 -0.5" mesh="part_1__7" material="part_1__7_material"/>
            <!-- Part peg_6 -->
            <geom type="mesh" class="visual" pos="8.85663e-05 -0.10395 0.045085" quat="2.22045e-16 -1.39694e-16 -0.707107 -0.707107" mesh="peg" material="peg_material"/>
            <geom type="mesh" class="collision" pos="8.85663e-05 -0.10395 0.045085" quat="2.22045e-16 -1.39694e-16 -0.707107 -0.707107" mesh="peg" material="peg_material"/>
            <!-- Part dc07_00a_dummy_none_10 -->
            <geom type="mesh" class="visual" pos="8.85663e-05 -0.12695 0.01771" quat="0 2.4694e-16 0 1" mesh="dc07_00a_dummy_none" material="dc07_00a_dummy_none_material"/>
            <geom type="mesh" class="collision" pos="8.85663e-05 -0.12695 0.01771" quat="0 2.4694e-16 0 1" mesh="dc07_00a_dummy_none" material="dc07_00a_dummy_none_material"/>
            <!-- Part peg_7 -->
            <geom type="mesh" class="visual" pos="8.85663e-05 -0.10395 -0.009665" quat="2.10942e-15 -4.9323e-15 0.707107 0.707107" mesh="peg" material="peg_material"/>
            <geom type="mesh" class="collision" pos="8.85663e-05 -0.10395 -0.009665" quat="2.10942e-15 -4.9323e-15 0.707107 0.707107" mesh="peg" material="peg_material"/>
            <!-- Part part_1_23 -->
            <geom type="mesh" class="visual" pos="8.85663e-05 -0.08895 -0.009665" quat="0.5 -0.5 0.5 0.5" mesh="part_1__7" material="part_1__7_material"/>
            <geom type="mesh" class="collision" pos="8.85663e-05 -0.08895 -0.009665" quat="0.5 -0.5 0.5 0.5" mesh="part_1__7" material="part_1__7_material"/>
            <!-- Link peg -->
            <body name="peg" pos="8.85663e-05 -0.12695 0.03546" quat="2.77556e-16 2.58585e-17 -1 -5.55112e-16">
              <!-- Joint from dc07_00a_dummy_none_2 to peg -->
              <joint axis="0 0 1" name="left knee" type="hinge" range="-1.5707963267948974 1.5707963267948957"/>
              <inertial pos="-8.85412e-05 -0.0702967 0.01771" mass="0.195615" fullinertia="0.000327822 5.05789e-05 0.000288749 1.56531e-08 8.54871e-20 -1.27997e-20"/>
              <!-- Part part_1_24 -->
              <geom type="mesh" class="visual" pos="-8.85663e-05 -0.15385 -0.009" quat="5.55112e-17 -9.25444e-17 -0.707107 0.707107" mesh="part_1__9" material="part_1__9_material"/>
              <geom type="mesh" class="collision" pos="-8.85663e-05 -0.15385 -0.009" quat="5.55112e-17 -9.25444e-17 -0.707107 0.707107" mesh="part_1__9" material="part_1__9_material"/>
              <!-- Part peg_8 -->
              <geom type="mesh" class="visual" pos="-8.85663e-05 -0.10395 0.01771" quat="0.707107 -0.707107 -1.11022e-16 -7.29459e-17" mesh="peg" material="peg_material"/>
              <geom type="mesh" class="collision" pos="-8.85663e-05 -0.10395 0.01771" quat="0.707107 -0.707107 -1.11022e-16 -7.29459e-17" mesh="peg" material="peg_material"/>
              <!-- Part part_1_25 -->
              <geom type="mesh" class="visual" pos="-8.85663e-05 0 -0.009" quat="0.707107 -0.707107 -1.11022e-16 -8.98677e-17" mesh="part_1__8" material="part_1__8_material"/>
              <geom type="mesh" class="collision" pos="-8.85663e-05 0 -0.009" quat="0.707107 -0.707107 -1.11022e-16 -8.98677e-17" mesh="part_1__8" material="part_1__8_material"/>
              <!-- Link part_1_8 -->
              <body name="part_1_8" pos="-0.000177133 -0.15385 0.03942" quat="8.32667e-17 1.33128e-16 2.22045e-16 -1">
                <!-- Joint from peg to part_1_8 -->
                <joint axis="0 0 1" name="left foot lift" type="hinge" range="-1.570796326794893 0.5235987755983024"/>
                <inertial pos="-0.0221492 -0.0114021 -0.0217662" mass="0.707082" fullinertia="0.000187139 0.000502965 0.000558646 -5.372e-06 2.65156e-07 -1.4311e-06"/>
                <!-- Part part_1_26 -->
                <geom type="mesh" class="visual" pos="-0.015 -0.0125 -0.00675" quat="9.99201e-16 8.54565e-16 0.707107 -0.707107" mesh="part_1__5" material="part_1__5_material"/>
                <geom type="mesh" class="collision" pos="-0.015 -0.0125 -0.00675" quat="9.99201e-16 8.54565e-16 0.707107 -0.707107" mesh="part_1__5" material="part_1__5_material"/>
                <!-- Part part_1_27 -->
                <geom type="mesh" class="visual" pos="0.01525 0.0085 -0.0218" quat="0.5 0.5 -0.5 0.5" mesh="part_1__4" material="part_1__4_material"/>
                <geom type="mesh" class="collision" pos="0.01525 0.0085 -0.0218" quat="0.5 0.5 -0.5 0.5" mesh="part_1__4" material="part_1__4_material"/>
                <!-- Part dc07_00a_dummy_none_11 -->
                <geom type="mesh" class="visual" pos="-0.04575 7.77156e-16 -0.02175" quat="0.707107 1.19743e-16 0.707107 1.11022e-16" mesh="dc07_00a_dummy_none" material="dc07_00a_dummy_none_material"/>
                <geom type="mesh" class="collision" pos="-0.04575 7.77156e-16 -0.02175" quat="0.707107 1.19743e-16 0.707107 1.11022e-16" mesh="dc07_00a_dummy_none" material="dc07_00a_dummy_none_material"/>
                <!-- Part part_1_28 -->
                <geom type="mesh" class="visual" pos="-0.015 -0.0125 -0.03675" quat="9.78384e-16 -9.6236e-16 0.707107 0.707107" mesh="part_1__5" material="part_1__5_material"/>
                <geom type="mesh" class="collision" pos="-0.015 -0.0125 -0.03675" quat="9.78384e-16 -9.6236e-16 0.707107 0.707107" mesh="part_1__5" material="part_1__5_material"/>
                <!-- Part dc07_00a_dummy_none_12 -->
                <geom type="mesh" class="visual" pos="-2.65413e-16 6.66134e-16 -0.02175" quat="1 -2.07323e-16 -6.66134e-16 4.71845e-16" mesh="dc07_00a_dummy_none" material="dc07_00a_dummy_none_material"/>
                <geom type="mesh" class="collision" pos="-2.65413e-16 6.66134e-16 -0.02175" quat="1 -2.07323e-16 -6.66134e-16 4.71845e-16" mesh="dc07_00a_dummy_none" material="dc07_00a_dummy_none_material"/>
                <!-- Link part_1_9 -->
                <body name="part_1_9" pos="0.022 2.04281e-14 -0.0218" quat="0.707107 -2.29352e-16 -0.707107 -4.996e-16">
                  <!-- Joint from part_1_8 to part_1_9 -->
                  <joint axis="0 0 1" name="left foot twist" type="hinge" range="-0.3490658503988659 0.3490658503988659"/>
                  <inertial pos="-0.00622102 0.0301908 0.0231366" mass="0.187872" fullinertia="0.000168904 0.000212446 6.00962e-05 2.25721e-06 5.44871e-07 -2.23578e-07"/>
                  <!-- Part part_1_29 -->
                  <geom type="mesh" class="visual" pos="-0.007 0.03695 0.0205" quat="0.707107 0.707107 1.11022e-16 1.48502e-17" mesh="part_1__12" material="part_1__12_material"/>
                  <geom type="mesh" class="collision" pos="-0.007 0.03695 0.0205" quat="0.707107 0.707107 1.11022e-16 1.48502e-17" mesh="part_1__12" material="part_1__12_material"/>
                  <!-- Part part_1_30 -->
                  <geom type="mesh" class="visual" pos="0 0 0.046" quat="0.707107 0.707107 0 -4.45095e-25" mesh="part_1__11" material="part_1__11_material"/>
                  <geom type="mesh" class="collision" pos="0 0 0.046" quat="0.707107 0.707107 0 -4.45095e-25" mesh="part_1__11" material="part_1__11_material"/>
                </body>
              </body>
            </body>
          </body>
        </body>
      </body>
    </body>
  </worldbody>
  <asset>
    <mesh file="part_1__10.stl"/>
    <mesh file="part_1__7.stl"/>
    <mesh file="part_1__12.stl"/>
    <mesh file="part_1__4.stl"/>
    <mesh file="arm_to_hand_link.stl"/>
    <mesh file="part_1__9.stl"/>
    <mesh file="shoulder_link.stl"/>
    <mesh file="body.stl"/>
    <mesh file="part_2.stl"/>
    <mesh file="peg.stl"/>
    <mesh file="part_1__3.stl"/>
    <mesh file="arm_link.stl"/>
    <mesh file="dc07_00a_dummy_none.stl"/>
    <mesh file="shoulder_to_arm_link.stl"/>
    <mesh file="part_1__11.stl"/>
    <mesh file="part_1__5.stl"/>
    <mesh file="part_1__8.stl"/>
    <mesh file="part_1__6.stl"/>
    <mesh file="shoulder_extension_motor.stl"/>
    <mesh file="part_1.stl"/>
    <mesh file="part_1__2.stl"/>
    <material name="dc07_00a_dummy_none_material" rgba="0.533333 0.533333 0.533333 1"/>
    <material name="shoulder_extension_motor_material" rgba="0.647059 0.647059 0.647059 1"/>
    <material name="part_1_material" rgba="0.615686 0.811765 0.929412 1"/>
    <material name="body_material" rgba="0.615686 0.811765 0.929412 1"/>
    <material name="part_2_material" rgba="0.701961 0.701961 0.701961 1"/>
    <material name="part_1__2_material" rgba="0.701961 0.701961 0.701961 1"/>
    <material name="shoulder_link_material" rgba="0.796078 0.823529 0.937255 1"/>
    <material name="arm_to_hand_link_material" rgba="0.615686 0.811765 0.929412 1"/>
    <material name="shoulder_to_arm_link_material" rgba="0.615686 0.811765 0.929412 1"/>
    <material name="peg_material" rgba="0.262745 0.282353 0.301961 1"/>
    <material name="arm_link_material" rgba="0.615686 0.811765 0.929412 1"/>
    <material name="part_1__3_material" rgba="0.615686 0.811765 0.929412 1"/>
    <material name="part_1__4_material" rgba="0.615686 0.811765 0.929412 1"/>
    <material name="part_1__5_material" rgba="0.615686 0.811765 0.929412 1"/>
    <material name="part_1__6_material" rgba="0.615686 0.811765 0.929412 1"/>
    <material name="part_1__7_material" rgba="0.615686 0.811765 0.929412 1"/>
    <material name="part_1__8_material" rgba="0.615686 0.811765 0.929412 1"/>
    <material name="part_1__9_material" rgba="0.615686 0.811765 0.929412 1"/>
    <material name="part_1__10_material" rgba="0.615686 0.811765 0.929412 1"/>
    <material name="part_1__11_material" rgba="0.615686 0.811765 0.929412 1"/>
    <material name="part_1__12_material" rgba="0.615686 0.811765 0.929412 1"/>
  </asset>
  <actuator>
    <position class="robot_env" name=" Shoulder front and back right" joint=" Shoulder front and back right" inheritrange="1"/>
    <position class="robot_env" name="Shoulder right lateral" joint="Shoulder right lateral" inheritrange="1"/>
    <position class="robot_env" name="right wrist" joint="right wrist" inheritrange="1"/>
    <position class="robot_env" name="Shoulder left front back" joint="Shoulder left front back" inheritrange="1"/>
    <position class="robot_env" name="shoulder left lateral" joint="shoulder left lateral" inheritrange="1"/>
    <position class="robot_env" name="left hand" joint="left hand" inheritrange="1"/>
    <position class="robot_env" name="right leg twist" joint="right leg twist" inheritrange="1"/>
    <position class="robot_env" name="right leg lateral" joint="right leg lateral" inheritrange="1"/>
    <position class="robot_env" name="right hammy" joint="right hammy" inheritrange="1"/>
    <position class="robot_env" name="right knee" joint="right knee" inheritrange="1"/>
    <position class="robot_env" name="right foot" joint="right foot" inheritrange="1"/>
    <position class="robot_env" name="right foot twist" joint="right foot twist" inheritrange="1"/>
    <position class="robot_env" name="left leg twist" joint="left leg twist" inheritrange="1"/>
    <position class="robot_env" name="left leg lateral" joint="left leg lateral" inheritrange="1"/>
    <position class="robot_env" name="left hammy" joint="left hammy" inheritrange="1"/>
    <position class="robot_env" name="left knee" joint="left knee" inheritrange="1"/>
    <position class="robot_env" name="left foot lift" joint="left foot lift" inheritrange="1"/>
    <position class="robot_env" name="left foot twist" joint="left foot twist" inheritrange="1"/>
  </actuator>
  <equality/>
</mujoco>
